2025-03-11 14:46:36,835 - kombu.connection - WARNING - No hostname was supplied. Reverting to default 'localhost'
2025-03-11 14:46:42,998 - django.request - ERROR - Internal Server Error: /rate_predictor/dashboard/
Traceback (most recent call last):
  File "D:\get_rate_zim\.venv\Lib\site-packages\kombu\utils\functional.py", line 32, in __call__
    return self.__value__
           ^^^^^^^^^^^^^^
AttributeError: 'ChannelPromise' object has no attribute '__value__'. Did you mean: '__call__'?

During handling of the above exception, another exception occurred:

Traceback (most recent call last):
  File "D:\get_rate_zim\.venv\Lib\site-packages\kombu\connection.py", line 472, in _reraise_as_library_errors
    yield
  File "D:\get_rate_zim\.venv\Lib\site-packages\kombu\connection.py", line 459, in _ensure_connection
    return retry_over_time(
           ^^^^^^^^^^^^^^^^
  File "D:\get_rate_zim\.venv\Lib\site-packages\kombu\utils\functional.py", line 318, in retry_over_time
    return fun(*args, **kwargs)
           ^^^^^^^^^^^^^^^^^^^^
  File "D:\get_rate_zim\.venv\Lib\site-packages\kombu\connection.py", line 934, in _connection_factory
    self._connection = self._establish_connection()
                       ^^^^^^^^^^^^^^^^^^^^^^^^^^^^
  File "D:\get_rate_zim\.venv\Lib\site-packages\kombu\connection.py", line 860, in _establish_connection
    conn = self.transport.establish_connection()
           ^^^^^^^^^^^^^^^^^^^^^^^^^^^^^^^^^^^^^
  File "D:\get_rate_zim\.venv\Lib\site-packages\kombu\transport\pyamqp.py", line 203, in establish_connection
    conn.connect()
  File "D:\get_rate_zim\.venv\Lib\site-packages\amqp\connection.py", line 324, in connect
    self.transport.connect()
  File "D:\get_rate_zim\.venv\Lib\site-packages\amqp\transport.py", line 132, in connect
    self._connect(self.host, self.port, self.connect_timeout)
  File "D:\get_rate_zim\.venv\Lib\site-packages\amqp\transport.py", line 187, in _connect
    self.sock.connect(sa)
ConnectionRefusedError: [WinError 10061] No connection could be made because the target machine actively refused it

The above exception was the direct cause of the following exception:

Traceback (most recent call last):
  File "D:\get_rate_zim\.venv\Lib\site-packages\django\core\handlers\exception.py", line 55, in inner
    response = get_response(request)
               ^^^^^^^^^^^^^^^^^^^^^
  File "D:\get_rate_zim\.venv\Lib\site-packages\django\core\handlers\base.py", line 197, in _get_response
    response = wrapped_callback(request, *callback_args, **callback_kwargs)
               ^^^^^^^^^^^^^^^^^^^^^^^^^^^^^^^^^^^^^^^^^^^^^^^^^^^^^^^^^^^^
  File "D:\get_rate_zim\.venv\Lib\site-packages\django\views\generic\base.py", line 104, in view
    return self.dispatch(request, *args, **kwargs)
           ^^^^^^^^^^^^^^^^^^^^^^^^^^^^^^^^^^^^^^^
  File "D:\get_rate_zim\.venv\Lib\site-packages\django\contrib\auth\mixins.py", line 73, in dispatch
    return super().dispatch(request, *args, **kwargs)
           ^^^^^^^^^^^^^^^^^^^^^^^^^^^^^^^^^^^^^^^^^^
  File "D:\get_rate_zim\.venv\Lib\site-packages\django\views\generic\base.py", line 143, in dispatch
    return handler(request, *args, **kwargs)
           ^^^^^^^^^^^^^^^^^^^^^^^^^^^^^^^^^
  File "D:\get_rate_zim\rate_predictor\views.py", line 172, in get
    task = update_model_task.delay(is_initial=initial_training_needed)
           ^^^^^^^^^^^^^^^^^^^^^^^^^^^^^^^^^^^^^^^^^^^^^^^^^^^^^^^^^^^
  File "D:\get_rate_zim\.venv\Lib\site-packages\celery\app\task.py", line 444, in delay
    return self.apply_async(args, kwargs)
           ^^^^^^^^^^^^^^^^^^^^^^^^^^^^^^
  File "D:\get_rate_zim\.venv\Lib\site-packages\celery\app\task.py", line 594, in apply_async
    return app.send_task(
           ^^^^^^^^^^^^^^
  File "D:\get_rate_zim\.venv\Lib\site-packages\celery\app\base.py", line 801, in send_task
    amqp.send_task_message(P, name, message, **options)
  File "D:\get_rate_zim\.venv\Lib\site-packages\celery\app\amqp.py", line 518, in send_task_message
    ret = producer.publish(
          ^^^^^^^^^^^^^^^^^
  File "D:\get_rate_zim\.venv\Lib\site-packages\kombu\messaging.py", line 186, in publish
    return _publish(
           ^^^^^^^^^
  File "D:\get_rate_zim\.venv\Lib\site-packages\kombu\connection.py", line 556, in _ensured
    return fun(*args, **kwargs)
           ^^^^^^^^^^^^^^^^^^^^
  File "D:\get_rate_zim\.venv\Lib\site-packages\kombu\messaging.py", line 195, in _publish
    channel = self.channel
              ^^^^^^^^^^^^
  File "D:\get_rate_zim\.venv\Lib\site-packages\kombu\messaging.py", line 218, in _get_channel
    channel = self._channel = channel()
                              ^^^^^^^^^
  File "D:\get_rate_zim\.venv\Lib\site-packages\kombu\utils\functional.py", line 34, in __call__
    value = self.__value__ = self.__contract__()
                             ^^^^^^^^^^^^^^^^^^^
  File "D:\get_rate_zim\.venv\Lib\site-packages\kombu\messaging.py", line 234, in <lambda>
    channel = ChannelPromise(lambda: connection.default_channel)
                                     ^^^^^^^^^^^^^^^^^^^^^^^^^^
  File "D:\get_rate_zim\.venv\Lib\site-packages\kombu\connection.py", line 953, in default_channel
    self._ensure_connection(**conn_opts)
  File "D:\get_rate_zim\.venv\Lib\site-packages\kombu\connection.py", line 458, in _ensure_connection
    with ctx():
  File "C:\Users\ashle\AppData\Local\Programs\Python\Python312\Lib\contextlib.py", line 158, in __exit__
    self.gen.throw(value)
  File "D:\get_rate_zim\.venv\Lib\site-packages\kombu\connection.py", line 476, in _reraise_as_library_errors
    raise ConnectionError(str(exc)) from exc
kombu.exceptions.OperationalError: [WinError 10061] No connection could be made because the target machine actively refused it
2025-03-11 14:48:07,577 - django.utils.autoreload - INFO - D:\get_rate_zim\get_rate_zim\settings.py changed, reloading.
2025-03-11 14:50:56,189 - kombu.connection - WARNING - No hostname was supplied. Reverting to default 'localhost'
2025-03-11 14:51:02,357 - django.request - ERROR - Internal Server Error: /rate_predictor/dashboard/
Traceback (most recent call last):
  File "D:\get_rate_zim\.venv\Lib\site-packages\kombu\utils\functional.py", line 32, in __call__
    return self.__value__
           ^^^^^^^^^^^^^^
AttributeError: 'ChannelPromise' object has no attribute '__value__'. Did you mean: '__call__'?

During handling of the above exception, another exception occurred:

Traceback (most recent call last):
  File "D:\get_rate_zim\.venv\Lib\site-packages\kombu\connection.py", line 472, in _reraise_as_library_errors
    yield
  File "D:\get_rate_zim\.venv\Lib\site-packages\kombu\connection.py", line 459, in _ensure_connection
    return retry_over_time(
           ^^^^^^^^^^^^^^^^
  File "D:\get_rate_zim\.venv\Lib\site-packages\kombu\utils\functional.py", line 318, in retry_over_time
    return fun(*args, **kwargs)
           ^^^^^^^^^^^^^^^^^^^^
  File "D:\get_rate_zim\.venv\Lib\site-packages\kombu\connection.py", line 934, in _connection_factory
    self._connection = self._establish_connection()
                       ^^^^^^^^^^^^^^^^^^^^^^^^^^^^
  File "D:\get_rate_zim\.venv\Lib\site-packages\kombu\connection.py", line 860, in _establish_connection
    conn = self.transport.establish_connection()
           ^^^^^^^^^^^^^^^^^^^^^^^^^^^^^^^^^^^^^
  File "D:\get_rate_zim\.venv\Lib\site-packages\kombu\transport\pyamqp.py", line 203, in establish_connection
    conn.connect()
  File "D:\get_rate_zim\.venv\Lib\site-packages\amqp\connection.py", line 324, in connect
    self.transport.connect()
  File "D:\get_rate_zim\.venv\Lib\site-packages\amqp\transport.py", line 132, in connect
    self._connect(self.host, self.port, self.connect_timeout)
  File "D:\get_rate_zim\.venv\Lib\site-packages\amqp\transport.py", line 187, in _connect
    self.sock.connect(sa)
ConnectionRefusedError: [WinError 10061] No connection could be made because the target machine actively refused it

The above exception was the direct cause of the following exception:

Traceback (most recent call last):
  File "D:\get_rate_zim\.venv\Lib\site-packages\django\core\handlers\exception.py", line 55, in inner
    response = get_response(request)
               ^^^^^^^^^^^^^^^^^^^^^
  File "D:\get_rate_zim\.venv\Lib\site-packages\django\core\handlers\base.py", line 197, in _get_response
    response = wrapped_callback(request, *callback_args, **callback_kwargs)
               ^^^^^^^^^^^^^^^^^^^^^^^^^^^^^^^^^^^^^^^^^^^^^^^^^^^^^^^^^^^^
  File "D:\get_rate_zim\.venv\Lib\site-packages\django\views\generic\base.py", line 104, in view
    return self.dispatch(request, *args, **kwargs)
           ^^^^^^^^^^^^^^^^^^^^^^^^^^^^^^^^^^^^^^^
  File "D:\get_rate_zim\.venv\Lib\site-packages\django\contrib\auth\mixins.py", line 73, in dispatch
    return super().dispatch(request, *args, **kwargs)
           ^^^^^^^^^^^^^^^^^^^^^^^^^^^^^^^^^^^^^^^^^^
  File "D:\get_rate_zim\.venv\Lib\site-packages\django\views\generic\base.py", line 143, in dispatch
    return handler(request, *args, **kwargs)
           ^^^^^^^^^^^^^^^^^^^^^^^^^^^^^^^^^
  File "D:\get_rate_zim\rate_predictor\views.py", line 172, in get
    task = update_model_task.delay(is_initial=initial_training_needed)
           ^^^^^^^^^^^^^^^^^^^^^^^^^^^^^^^^^^^^^^^^^^^^^^^^^^^^^^^^^^^
  File "D:\get_rate_zim\.venv\Lib\site-packages\celery\app\task.py", line 444, in delay
    return self.apply_async(args, kwargs)
           ^^^^^^^^^^^^^^^^^^^^^^^^^^^^^^
  File "D:\get_rate_zim\.venv\Lib\site-packages\celery\app\task.py", line 594, in apply_async
    return app.send_task(
           ^^^^^^^^^^^^^^
  File "D:\get_rate_zim\.venv\Lib\site-packages\celery\app\base.py", line 801, in send_task
    amqp.send_task_message(P, name, message, **options)
  File "D:\get_rate_zim\.venv\Lib\site-packages\celery\app\amqp.py", line 518, in send_task_message
    ret = producer.publish(
          ^^^^^^^^^^^^^^^^^
  File "D:\get_rate_zim\.venv\Lib\site-packages\kombu\messaging.py", line 186, in publish
    return _publish(
           ^^^^^^^^^
  File "D:\get_rate_zim\.venv\Lib\site-packages\kombu\connection.py", line 556, in _ensured
    return fun(*args, **kwargs)
           ^^^^^^^^^^^^^^^^^^^^
  File "D:\get_rate_zim\.venv\Lib\site-packages\kombu\messaging.py", line 195, in _publish
    channel = self.channel
              ^^^^^^^^^^^^
  File "D:\get_rate_zim\.venv\Lib\site-packages\kombu\messaging.py", line 218, in _get_channel
    channel = self._channel = channel()
                              ^^^^^^^^^
  File "D:\get_rate_zim\.venv\Lib\site-packages\kombu\utils\functional.py", line 34, in __call__
    value = self.__value__ = self.__contract__()
                             ^^^^^^^^^^^^^^^^^^^
  File "D:\get_rate_zim\.venv\Lib\site-packages\kombu\messaging.py", line 234, in <lambda>
    channel = ChannelPromise(lambda: connection.default_channel)
                                     ^^^^^^^^^^^^^^^^^^^^^^^^^^
  File "D:\get_rate_zim\.venv\Lib\site-packages\kombu\connection.py", line 953, in default_channel
    self._ensure_connection(**conn_opts)
  File "D:\get_rate_zim\.venv\Lib\site-packages\kombu\connection.py", line 458, in _ensure_connection
    with ctx():
  File "C:\Users\ashle\AppData\Local\Programs\Python\Python312\Lib\contextlib.py", line 158, in __exit__
    self.gen.throw(value)
  File "D:\get_rate_zim\.venv\Lib\site-packages\kombu\connection.py", line 476, in _reraise_as_library_errors
    raise ConnectionError(str(exc)) from exc
kombu.exceptions.OperationalError: [WinError 10061] No connection could be made because the target machine actively refused it
2025-03-11 14:53:18,605 - django.utils.autoreload - INFO - D:\get_rate_zim\get_rate_zim\settings.py changed, reloading.
2025-03-11 14:58:03,419 - kombu.connection - WARNING - No hostname was supplied. Reverting to default 'localhost'
2025-03-11 14:58:09,550 - django.request - ERROR - Internal Server Error: /rate_predictor/dashboard/
Traceback (most recent call last):
  File "D:\get_rate_zim\.venv\Lib\site-packages\kombu\utils\functional.py", line 32, in __call__
    return self.__value__
           ^^^^^^^^^^^^^^
AttributeError: 'ChannelPromise' object has no attribute '__value__'. Did you mean: '__call__'?

During handling of the above exception, another exception occurred:

Traceback (most recent call last):
  File "D:\get_rate_zim\.venv\Lib\site-packages\kombu\connection.py", line 472, in _reraise_as_library_errors
    yield
  File "D:\get_rate_zim\.venv\Lib\site-packages\kombu\connection.py", line 459, in _ensure_connection
    return retry_over_time(
           ^^^^^^^^^^^^^^^^
  File "D:\get_rate_zim\.venv\Lib\site-packages\kombu\utils\functional.py", line 318, in retry_over_time
    return fun(*args, **kwargs)
           ^^^^^^^^^^^^^^^^^^^^
  File "D:\get_rate_zim\.venv\Lib\site-packages\kombu\connection.py", line 934, in _connection_factory
    self._connection = self._establish_connection()
                       ^^^^^^^^^^^^^^^^^^^^^^^^^^^^
  File "D:\get_rate_zim\.venv\Lib\site-packages\kombu\connection.py", line 860, in _establish_connection
    conn = self.transport.establish_connection()
           ^^^^^^^^^^^^^^^^^^^^^^^^^^^^^^^^^^^^^
  File "D:\get_rate_zim\.venv\Lib\site-packages\kombu\transport\pyamqp.py", line 203, in establish_connection
    conn.connect()
  File "D:\get_rate_zim\.venv\Lib\site-packages\amqp\connection.py", line 324, in connect
    self.transport.connect()
  File "D:\get_rate_zim\.venv\Lib\site-packages\amqp\transport.py", line 132, in connect
    self._connect(self.host, self.port, self.connect_timeout)
  File "D:\get_rate_zim\.venv\Lib\site-packages\amqp\transport.py", line 187, in _connect
    self.sock.connect(sa)
ConnectionRefusedError: [WinError 10061] No connection could be made because the target machine actively refused it

The above exception was the direct cause of the following exception:

Traceback (most recent call last):
  File "D:\get_rate_zim\.venv\Lib\site-packages\django\core\handlers\exception.py", line 55, in inner
    response = get_response(request)
               ^^^^^^^^^^^^^^^^^^^^^
  File "D:\get_rate_zim\.venv\Lib\site-packages\django\core\handlers\base.py", line 197, in _get_response
    response = wrapped_callback(request, *callback_args, **callback_kwargs)
               ^^^^^^^^^^^^^^^^^^^^^^^^^^^^^^^^^^^^^^^^^^^^^^^^^^^^^^^^^^^^
  File "D:\get_rate_zim\.venv\Lib\site-packages\django\views\generic\base.py", line 104, in view
    return self.dispatch(request, *args, **kwargs)
           ^^^^^^^^^^^^^^^^^^^^^^^^^^^^^^^^^^^^^^^
  File "D:\get_rate_zim\.venv\Lib\site-packages\django\contrib\auth\mixins.py", line 73, in dispatch
    return super().dispatch(request, *args, **kwargs)
           ^^^^^^^^^^^^^^^^^^^^^^^^^^^^^^^^^^^^^^^^^^
  File "D:\get_rate_zim\.venv\Lib\site-packages\django\views\generic\base.py", line 143, in dispatch
    return handler(request, *args, **kwargs)
           ^^^^^^^^^^^^^^^^^^^^^^^^^^^^^^^^^
  File "D:\get_rate_zim\rate_predictor\views.py", line 172, in get
    task = update_model_task.delay(is_initial=initial_training_needed)
           ^^^^^^^^^^^^^^^^^^^^^^^^^^^^^^^^^^^^^^^^^^^^^^^^^^^^^^^^^^^
  File "D:\get_rate_zim\.venv\Lib\site-packages\celery\app\task.py", line 444, in delay
    return self.apply_async(args, kwargs)
           ^^^^^^^^^^^^^^^^^^^^^^^^^^^^^^
  File "D:\get_rate_zim\.venv\Lib\site-packages\celery\app\task.py", line 594, in apply_async
    return app.send_task(
           ^^^^^^^^^^^^^^
  File "D:\get_rate_zim\.venv\Lib\site-packages\celery\app\base.py", line 801, in send_task
    amqp.send_task_message(P, name, message, **options)
  File "D:\get_rate_zim\.venv\Lib\site-packages\celery\app\amqp.py", line 518, in send_task_message
    ret = producer.publish(
          ^^^^^^^^^^^^^^^^^
  File "D:\get_rate_zim\.venv\Lib\site-packages\kombu\messaging.py", line 186, in publish
    return _publish(
           ^^^^^^^^^
  File "D:\get_rate_zim\.venv\Lib\site-packages\kombu\connection.py", line 556, in _ensured
    return fun(*args, **kwargs)
           ^^^^^^^^^^^^^^^^^^^^
  File "D:\get_rate_zim\.venv\Lib\site-packages\kombu\messaging.py", line 195, in _publish
    channel = self.channel
              ^^^^^^^^^^^^
  File "D:\get_rate_zim\.venv\Lib\site-packages\kombu\messaging.py", line 218, in _get_channel
    channel = self._channel = channel()
                              ^^^^^^^^^
  File "D:\get_rate_zim\.venv\Lib\site-packages\kombu\utils\functional.py", line 34, in __call__
    value = self.__value__ = self.__contract__()
                             ^^^^^^^^^^^^^^^^^^^
  File "D:\get_rate_zim\.venv\Lib\site-packages\kombu\messaging.py", line 234, in <lambda>
    channel = ChannelPromise(lambda: connection.default_channel)
                                     ^^^^^^^^^^^^^^^^^^^^^^^^^^
  File "D:\get_rate_zim\.venv\Lib\site-packages\kombu\connection.py", line 953, in default_channel
    self._ensure_connection(**conn_opts)
  File "D:\get_rate_zim\.venv\Lib\site-packages\kombu\connection.py", line 458, in _ensure_connection
    with ctx():
  File "C:\Users\ashle\AppData\Local\Programs\Python\Python312\Lib\contextlib.py", line 158, in __exit__
    self.gen.throw(value)
  File "D:\get_rate_zim\.venv\Lib\site-packages\kombu\connection.py", line 476, in _reraise_as_library_errors
    raise ConnectionError(str(exc)) from exc
kombu.exceptions.OperationalError: [WinError 10061] No connection could be made because the target machine actively refused it
2025-03-11 14:58:34,686 - django.request - ERROR - Internal Server Error: /rate_predictor/dashboard/
Traceback (most recent call last):
  File "D:\get_rate_zim\.venv\Lib\site-packages\kombu\utils\functional.py", line 32, in __call__
    return self.__value__
           ^^^^^^^^^^^^^^
AttributeError: 'ChannelPromise' object has no attribute '__value__'. Did you mean: '__call__'?

During handling of the above exception, another exception occurred:

Traceback (most recent call last):
  File "D:\get_rate_zim\.venv\Lib\site-packages\kombu\connection.py", line 472, in _reraise_as_library_errors
    yield
  File "D:\get_rate_zim\.venv\Lib\site-packages\kombu\connection.py", line 459, in _ensure_connection
    return retry_over_time(
           ^^^^^^^^^^^^^^^^
  File "D:\get_rate_zim\.venv\Lib\site-packages\kombu\utils\functional.py", line 318, in retry_over_time
    return fun(*args, **kwargs)
           ^^^^^^^^^^^^^^^^^^^^
  File "D:\get_rate_zim\.venv\Lib\site-packages\kombu\connection.py", line 934, in _connection_factory
    self._connection = self._establish_connection()
                       ^^^^^^^^^^^^^^^^^^^^^^^^^^^^
  File "D:\get_rate_zim\.venv\Lib\site-packages\kombu\connection.py", line 860, in _establish_connection
    conn = self.transport.establish_connection()
           ^^^^^^^^^^^^^^^^^^^^^^^^^^^^^^^^^^^^^
  File "D:\get_rate_zim\.venv\Lib\site-packages\kombu\transport\pyamqp.py", line 203, in establish_connection
    conn.connect()
  File "D:\get_rate_zim\.venv\Lib\site-packages\amqp\connection.py", line 324, in connect
    self.transport.connect()
  File "D:\get_rate_zim\.venv\Lib\site-packages\amqp\transport.py", line 132, in connect
    self._connect(self.host, self.port, self.connect_timeout)
  File "D:\get_rate_zim\.venv\Lib\site-packages\amqp\transport.py", line 187, in _connect
    self.sock.connect(sa)
ConnectionRefusedError: [WinError 10061] No connection could be made because the target machine actively refused it

The above exception was the direct cause of the following exception:

Traceback (most recent call last):
  File "D:\get_rate_zim\.venv\Lib\site-packages\django\core\handlers\exception.py", line 55, in inner
    response = get_response(request)
               ^^^^^^^^^^^^^^^^^^^^^
  File "D:\get_rate_zim\.venv\Lib\site-packages\django\core\handlers\base.py", line 197, in _get_response
    response = wrapped_callback(request, *callback_args, **callback_kwargs)
               ^^^^^^^^^^^^^^^^^^^^^^^^^^^^^^^^^^^^^^^^^^^^^^^^^^^^^^^^^^^^
  File "D:\get_rate_zim\.venv\Lib\site-packages\django\views\generic\base.py", line 104, in view
    return self.dispatch(request, *args, **kwargs)
           ^^^^^^^^^^^^^^^^^^^^^^^^^^^^^^^^^^^^^^^
  File "D:\get_rate_zim\.venv\Lib\site-packages\django\contrib\auth\mixins.py", line 73, in dispatch
    return super().dispatch(request, *args, **kwargs)
           ^^^^^^^^^^^^^^^^^^^^^^^^^^^^^^^^^^^^^^^^^^
  File "D:\get_rate_zim\.venv\Lib\site-packages\django\views\generic\base.py", line 143, in dispatch
    return handler(request, *args, **kwargs)
           ^^^^^^^^^^^^^^^^^^^^^^^^^^^^^^^^^
  File "D:\get_rate_zim\rate_predictor\views.py", line 172, in get
    task = update_model_task.delay(is_initial=initial_training_needed)
           ^^^^^^^^^^^^^^^^^^^^^^^^^^^^^^^^^^^^^^^^^^^^^^^^^^^^^^^^^^^
  File "D:\get_rate_zim\.venv\Lib\site-packages\celery\app\task.py", line 444, in delay
    return self.apply_async(args, kwargs)
           ^^^^^^^^^^^^^^^^^^^^^^^^^^^^^^
  File "D:\get_rate_zim\.venv\Lib\site-packages\celery\app\task.py", line 594, in apply_async
    return app.send_task(
           ^^^^^^^^^^^^^^
  File "D:\get_rate_zim\.venv\Lib\site-packages\celery\app\base.py", line 801, in send_task
    amqp.send_task_message(P, name, message, **options)
  File "D:\get_rate_zim\.venv\Lib\site-packages\celery\app\amqp.py", line 518, in send_task_message
    ret = producer.publish(
          ^^^^^^^^^^^^^^^^^
  File "D:\get_rate_zim\.venv\Lib\site-packages\kombu\messaging.py", line 186, in publish
    return _publish(
           ^^^^^^^^^
  File "D:\get_rate_zim\.venv\Lib\site-packages\kombu\connection.py", line 556, in _ensured
    return fun(*args, **kwargs)
           ^^^^^^^^^^^^^^^^^^^^
  File "D:\get_rate_zim\.venv\Lib\site-packages\kombu\messaging.py", line 195, in _publish
    channel = self.channel
              ^^^^^^^^^^^^
  File "D:\get_rate_zim\.venv\Lib\site-packages\kombu\messaging.py", line 218, in _get_channel
    channel = self._channel = channel()
                              ^^^^^^^^^
  File "D:\get_rate_zim\.venv\Lib\site-packages\kombu\utils\functional.py", line 34, in __call__
    value = self.__value__ = self.__contract__()
                             ^^^^^^^^^^^^^^^^^^^
  File "D:\get_rate_zim\.venv\Lib\site-packages\kombu\messaging.py", line 234, in <lambda>
    channel = ChannelPromise(lambda: connection.default_channel)
                                     ^^^^^^^^^^^^^^^^^^^^^^^^^^
  File "D:\get_rate_zim\.venv\Lib\site-packages\kombu\connection.py", line 953, in default_channel
    self._ensure_connection(**conn_opts)
  File "D:\get_rate_zim\.venv\Lib\site-packages\kombu\connection.py", line 458, in _ensure_connection
    with ctx():
  File "C:\Users\ashle\AppData\Local\Programs\Python\Python312\Lib\contextlib.py", line 158, in __exit__
    self.gen.throw(value)
  File "D:\get_rate_zim\.venv\Lib\site-packages\kombu\connection.py", line 476, in _reraise_as_library_errors
    raise ConnectionError(str(exc)) from exc
kombu.exceptions.OperationalError: [WinError 10061] No connection could be made because the target machine actively refused it
2025-03-11 14:59:56,323 - django.utils.autoreload - INFO - D:\get_rate_zim\get_rate_zim\settings.py changed, reloading.
2025-03-11 15:03:14,617 - kombu.connection - WARNING - No hostname was supplied. Reverting to default 'localhost'
2025-03-11 15:03:20,765 - django.request - ERROR - Internal Server Error: /rate_predictor/dashboard/
Traceback (most recent call last):
  File "D:\get_rate_zim\.venv\Lib\site-packages\kombu\utils\functional.py", line 32, in __call__
    return self.__value__
           ^^^^^^^^^^^^^^
AttributeError: 'ChannelPromise' object has no attribute '__value__'. Did you mean: '__call__'?

During handling of the above exception, another exception occurred:

Traceback (most recent call last):
  File "D:\get_rate_zim\.venv\Lib\site-packages\kombu\connection.py", line 472, in _reraise_as_library_errors
    yield
  File "D:\get_rate_zim\.venv\Lib\site-packages\kombu\connection.py", line 459, in _ensure_connection
    return retry_over_time(
           ^^^^^^^^^^^^^^^^
  File "D:\get_rate_zim\.venv\Lib\site-packages\kombu\utils\functional.py", line 318, in retry_over_time
    return fun(*args, **kwargs)
           ^^^^^^^^^^^^^^^^^^^^
  File "D:\get_rate_zim\.venv\Lib\site-packages\kombu\connection.py", line 934, in _connection_factory
    self._connection = self._establish_connection()
                       ^^^^^^^^^^^^^^^^^^^^^^^^^^^^
  File "D:\get_rate_zim\.venv\Lib\site-packages\kombu\connection.py", line 860, in _establish_connection
    conn = self.transport.establish_connection()
           ^^^^^^^^^^^^^^^^^^^^^^^^^^^^^^^^^^^^^
  File "D:\get_rate_zim\.venv\Lib\site-packages\kombu\transport\pyamqp.py", line 203, in establish_connection
    conn.connect()
  File "D:\get_rate_zim\.venv\Lib\site-packages\amqp\connection.py", line 324, in connect
    self.transport.connect()
  File "D:\get_rate_zim\.venv\Lib\site-packages\amqp\transport.py", line 132, in connect
    self._connect(self.host, self.port, self.connect_timeout)
  File "D:\get_rate_zim\.venv\Lib\site-packages\amqp\transport.py", line 187, in _connect
    self.sock.connect(sa)
ConnectionRefusedError: [WinError 10061] No connection could be made because the target machine actively refused it

The above exception was the direct cause of the following exception:

Traceback (most recent call last):
  File "D:\get_rate_zim\rate_predictor\views.py", line 176, in get
    update_model_task.delay(is_initial=initial_training_needed)
  File "D:\get_rate_zim\.venv\Lib\site-packages\celery\app\task.py", line 444, in delay
    return self.apply_async(args, kwargs)
           ^^^^^^^^^^^^^^^^^^^^^^^^^^^^^^
  File "D:\get_rate_zim\.venv\Lib\site-packages\celery\app\task.py", line 594, in apply_async
    return app.send_task(
           ^^^^^^^^^^^^^^
  File "D:\get_rate_zim\.venv\Lib\site-packages\celery\app\base.py", line 801, in send_task
    amqp.send_task_message(P, name, message, **options)
  File "D:\get_rate_zim\.venv\Lib\site-packages\celery\app\amqp.py", line 518, in send_task_message
    ret = producer.publish(
          ^^^^^^^^^^^^^^^^^
  File "D:\get_rate_zim\.venv\Lib\site-packages\kombu\messaging.py", line 186, in publish
    return _publish(
           ^^^^^^^^^
  File "D:\get_rate_zim\.venv\Lib\site-packages\kombu\connection.py", line 556, in _ensured
    return fun(*args, **kwargs)
           ^^^^^^^^^^^^^^^^^^^^
  File "D:\get_rate_zim\.venv\Lib\site-packages\kombu\messaging.py", line 195, in _publish
    channel = self.channel
              ^^^^^^^^^^^^
  File "D:\get_rate_zim\.venv\Lib\site-packages\kombu\messaging.py", line 218, in _get_channel
    channel = self._channel = channel()
                              ^^^^^^^^^
  File "D:\get_rate_zim\.venv\Lib\site-packages\kombu\utils\functional.py", line 34, in __call__
    value = self.__value__ = self.__contract__()
                             ^^^^^^^^^^^^^^^^^^^
  File "D:\get_rate_zim\.venv\Lib\site-packages\kombu\messaging.py", line 234, in <lambda>
    channel = ChannelPromise(lambda: connection.default_channel)
                                     ^^^^^^^^^^^^^^^^^^^^^^^^^^
  File "D:\get_rate_zim\.venv\Lib\site-packages\kombu\connection.py", line 953, in default_channel
    self._ensure_connection(**conn_opts)
  File "D:\get_rate_zim\.venv\Lib\site-packages\kombu\connection.py", line 458, in _ensure_connection
    with ctx():
  File "C:\Users\ashle\AppData\Local\Programs\Python\Python312\Lib\contextlib.py", line 158, in __exit__
    self.gen.throw(value)
  File "D:\get_rate_zim\.venv\Lib\site-packages\kombu\connection.py", line 476, in _reraise_as_library_errors
    raise ConnectionError(str(exc)) from exc
kombu.exceptions.OperationalError: [WinError 10061] No connection could be made because the target machine actively refused it

During handling of the above exception, another exception occurred:

Traceback (most recent call last):
  File "D:\get_rate_zim\.venv\Lib\site-packages\django\core\handlers\exception.py", line 55, in inner
    response = get_response(request)
               ^^^^^^^^^^^^^^^^^^^^^
  File "D:\get_rate_zim\.venv\Lib\site-packages\django\core\handlers\base.py", line 197, in _get_response
    response = wrapped_callback(request, *callback_args, **callback_kwargs)
               ^^^^^^^^^^^^^^^^^^^^^^^^^^^^^^^^^^^^^^^^^^^^^^^^^^^^^^^^^^^^
  File "D:\get_rate_zim\.venv\Lib\site-packages\django\views\generic\base.py", line 104, in view
    return self.dispatch(request, *args, **kwargs)
           ^^^^^^^^^^^^^^^^^^^^^^^^^^^^^^^^^^^^^^^
  File "D:\get_rate_zim\.venv\Lib\site-packages\django\contrib\auth\mixins.py", line 73, in dispatch
    return super().dispatch(request, *args, **kwargs)
           ^^^^^^^^^^^^^^^^^^^^^^^^^^^^^^^^^^^^^^^^^^
  File "D:\get_rate_zim\.venv\Lib\site-packages\django\views\generic\base.py", line 143, in dispatch
    return handler(request, *args, **kwargs)
           ^^^^^^^^^^^^^^^^^^^^^^^^^^^^^^^^^
  File "D:\get_rate_zim\rate_predictor\views.py", line 179, in get
    logger.error(f"Error in dashboard task execution: {e}")
    ^^^^^^
NameError: name 'logger' is not defined
2025-03-11 15:05:33,928 - django.utils.autoreload - INFO - D:\get_rate_zim\rate_predictor\views.py changed, reloading.
2025-03-11 15:05:55,100 - kombu.connection - WARNING - No hostname was supplied. Reverting to default 'localhost'
2025-03-11 15:06:01,197 - rate_predictor.views - ERROR - Error in dashboard task execution: [WinError 10061] No connection could be made because the target machine actively refused it
2025-03-11 15:06:09,072 - django.request - ERROR - Internal Server Error: /rate_predictor/dashboard/
Traceback (most recent call last):
  File "D:\get_rate_zim\.venv\Lib\site-packages\django\core\handlers\exception.py", line 55, in inner
    response = get_response(request)
               ^^^^^^^^^^^^^^^^^^^^^
  File "D:\get_rate_zim\.venv\Lib\site-packages\django\core\handlers\base.py", line 220, in _get_response
    response = response.render()
               ^^^^^^^^^^^^^^^^^
  File "D:\get_rate_zim\.venv\Lib\site-packages\django\template\response.py", line 114, in render
    self.content = self.rendered_content
                   ^^^^^^^^^^^^^^^^^^^^^
  File "D:\get_rate_zim\.venv\Lib\site-packages\django\template\response.py", line 90, in rendered_content
    template = self.resolve_template(self.template_name)
               ^^^^^^^^^^^^^^^^^^^^^^^^^^^^^^^^^^^^^^^^^
  File "D:\get_rate_zim\.venv\Lib\site-packages\django\template\response.py", line 72, in resolve_template
    return select_template(template, using=self.using)
           ^^^^^^^^^^^^^^^^^^^^^^^^^^^^^^^^^^^^^^^^^^^
  File "D:\get_rate_zim\.venv\Lib\site-packages\django\template\loader.py", line 42, in select_template
    return engine.get_template(template_name)
           ^^^^^^^^^^^^^^^^^^^^^^^^^^^^^^^^^^
  File "D:\get_rate_zim\.venv\Lib\site-packages\django\template\backends\django.py", line 79, in get_template
    return Template(self.engine.get_template(template_name), self)
                    ^^^^^^^^^^^^^^^^^^^^^^^^^^^^^^^^^^^^^^^
  File "D:\get_rate_zim\.venv\Lib\site-packages\django\template\engine.py", line 177, in get_template
    template, origin = self.find_template(template_name)
                       ^^^^^^^^^^^^^^^^^^^^^^^^^^^^^^^^^
  File "D:\get_rate_zim\.venv\Lib\site-packages\django\template\engine.py", line 159, in find_template
    template = loader.get_template(name, skip=skip)
               ^^^^^^^^^^^^^^^^^^^^^^^^^^^^^^^^^^^^
  File "D:\get_rate_zim\.venv\Lib\site-packages\django\template\loaders\cached.py", line 57, in get_template
    template = super().get_template(template_name, skip)
               ^^^^^^^^^^^^^^^^^^^^^^^^^^^^^^^^^^^^^^^^^
  File "D:\get_rate_zim\.venv\Lib\site-packages\django\template\loaders\base.py", line 28, in get_template
    return Template(
           ^^^^^^^^^
  File "D:\get_rate_zim\.venv\Lib\site-packages\django\template\base.py", line 154, in __init__
    self.nodelist = self.compile_nodelist()
                    ^^^^^^^^^^^^^^^^^^^^^^^
  File "D:\get_rate_zim\.venv\Lib\site-packages\django\template\base.py", line 196, in compile_nodelist
    nodelist = parser.parse()
               ^^^^^^^^^^^^^^
  File "D:\get_rate_zim\.venv\Lib\site-packages\django\template\base.py", line 518, in parse
    raise self.error(token, e)
  File "D:\get_rate_zim\.venv\Lib\site-packages\django\template\base.py", line 516, in parse
    compiled_result = compile_func(self, token)
                      ^^^^^^^^^^^^^^^^^^^^^^^^^
  File "D:\get_rate_zim\.venv\Lib\site-packages\django\template\loader_tags.py", line 295, in do_extends
    nodelist = parser.parse()
               ^^^^^^^^^^^^^^
  File "D:\get_rate_zim\.venv\Lib\site-packages\django\template\base.py", line 518, in parse
    raise self.error(token, e)
  File "D:\get_rate_zim\.venv\Lib\site-packages\django\template\base.py", line 516, in parse
    compiled_result = compile_func(self, token)
                      ^^^^^^^^^^^^^^^^^^^^^^^^^
  File "D:\get_rate_zim\.venv\Lib\site-packages\django\template\loader_tags.py", line 234, in do_block
    nodelist = parser.parse(("endblock",))
               ^^^^^^^^^^^^^^^^^^^^^^^^^^^
  File "D:\get_rate_zim\.venv\Lib\site-packages\django\template\base.py", line 518, in parse
    raise self.error(token, e)
  File "D:\get_rate_zim\.venv\Lib\site-packages\django\template\base.py", line 516, in parse
    compiled_result = compile_func(self, token)
                      ^^^^^^^^^^^^^^^^^^^^^^^^^
  File "D:\get_rate_zim\.venv\Lib\site-packages\django\template\defaulttags.py", line 962, in do_if
    nodelist = parser.parse(("elif", "else", "endif"))
               ^^^^^^^^^^^^^^^^^^^^^^^^^^^^^^^^^^^^^^^
  File "D:\get_rate_zim\.venv\Lib\site-packages\django\template\base.py", line 489, in parse
    raise self.error(token, e)
  File "D:\get_rate_zim\.venv\Lib\site-packages\django\template\base.py", line 487, in parse
    filter_expression = self.compile_filter(token.contents)
                        ^^^^^^^^^^^^^^^^^^^^^^^^^^^^^^^^^^^
  File "D:\get_rate_zim\.venv\Lib\site-packages\django\template\base.py", line 605, in compile_filter
    return FilterExpression(token, self)
           ^^^^^^^^^^^^^^^^^^^^^^^^^^^^^
  File "D:\get_rate_zim\.venv\Lib\site-packages\django\template\base.py", line 701, in __init__
    filter_func = parser.find_filter(filter_name)
                  ^^^^^^^^^^^^^^^^^^^^^^^^^^^^^^^
  File "D:\get_rate_zim\.venv\Lib\site-packages\django\template\base.py", line 611, in find_filter
    raise TemplateSyntaxError("Invalid filter: '%s'" % filter_name)
django.template.exceptions.TemplateSyntaxError: Invalid filter: 'mul'
2025-03-11 15:10:17,227 - django.utils.autoreload - INFO - D:\get_rate_zim\rate_predictor\templatetags\custom_filters.py changed, reloading.
2025-03-11 15:10:29,587 - kombu.connection - WARNING - No hostname was supplied. Reverting to default 'localhost'
2025-03-11 15:10:35,679 - rate_predictor.views - ERROR - Error in dashboard task execution: [WinError 10061] No connection could be made because the target machine actively refused it
2025-03-11 15:10:37,025 - django.request - ERROR - Internal Server Error: /rate_predictor/dashboard/
Traceback (most recent call last):
  File "D:\get_rate_zim\.venv\Lib\site-packages\django\core\handlers\exception.py", line 55, in inner
    response = get_response(request)
               ^^^^^^^^^^^^^^^^^^^^^
  File "D:\get_rate_zim\.venv\Lib\site-packages\django\core\handlers\base.py", line 220, in _get_response
    response = response.render()
               ^^^^^^^^^^^^^^^^^
  File "D:\get_rate_zim\.venv\Lib\site-packages\django\template\response.py", line 114, in render
    self.content = self.rendered_content
                   ^^^^^^^^^^^^^^^^^^^^^
  File "D:\get_rate_zim\.venv\Lib\site-packages\django\template\response.py", line 90, in rendered_content
    template = self.resolve_template(self.template_name)
               ^^^^^^^^^^^^^^^^^^^^^^^^^^^^^^^^^^^^^^^^^
  File "D:\get_rate_zim\.venv\Lib\site-packages\django\template\response.py", line 72, in resolve_template
    return select_template(template, using=self.using)
           ^^^^^^^^^^^^^^^^^^^^^^^^^^^^^^^^^^^^^^^^^^^
  File "D:\get_rate_zim\.venv\Lib\site-packages\django\template\loader.py", line 42, in select_template
    return engine.get_template(template_name)
           ^^^^^^^^^^^^^^^^^^^^^^^^^^^^^^^^^^
  File "D:\get_rate_zim\.venv\Lib\site-packages\django\template\backends\django.py", line 79, in get_template
    return Template(self.engine.get_template(template_name), self)
                    ^^^^^^^^^^^^^^^^^^^^^^^^^^^^^^^^^^^^^^^
  File "D:\get_rate_zim\.venv\Lib\site-packages\django\template\engine.py", line 177, in get_template
    template, origin = self.find_template(template_name)
                       ^^^^^^^^^^^^^^^^^^^^^^^^^^^^^^^^^
  File "D:\get_rate_zim\.venv\Lib\site-packages\django\template\engine.py", line 159, in find_template
    template = loader.get_template(name, skip=skip)
               ^^^^^^^^^^^^^^^^^^^^^^^^^^^^^^^^^^^^
  File "D:\get_rate_zim\.venv\Lib\site-packages\django\template\loaders\cached.py", line 57, in get_template
    template = super().get_template(template_name, skip)
               ^^^^^^^^^^^^^^^^^^^^^^^^^^^^^^^^^^^^^^^^^
  File "D:\get_rate_zim\.venv\Lib\site-packages\django\template\loaders\base.py", line 28, in get_template
    return Template(
           ^^^^^^^^^
  File "D:\get_rate_zim\.venv\Lib\site-packages\django\template\base.py", line 154, in __init__
    self.nodelist = self.compile_nodelist()
                    ^^^^^^^^^^^^^^^^^^^^^^^
  File "D:\get_rate_zim\.venv\Lib\site-packages\django\template\base.py", line 196, in compile_nodelist
    nodelist = parser.parse()
               ^^^^^^^^^^^^^^
  File "D:\get_rate_zim\.venv\Lib\site-packages\django\template\base.py", line 518, in parse
    raise self.error(token, e)
  File "D:\get_rate_zim\.venv\Lib\site-packages\django\template\base.py", line 516, in parse
    compiled_result = compile_func(self, token)
                      ^^^^^^^^^^^^^^^^^^^^^^^^^
  File "D:\get_rate_zim\.venv\Lib\site-packages\django\template\loader_tags.py", line 295, in do_extends
    nodelist = parser.parse()
               ^^^^^^^^^^^^^^
  File "D:\get_rate_zim\.venv\Lib\site-packages\django\template\base.py", line 518, in parse
    raise self.error(token, e)
  File "D:\get_rate_zim\.venv\Lib\site-packages\django\template\base.py", line 516, in parse
    compiled_result = compile_func(self, token)
                      ^^^^^^^^^^^^^^^^^^^^^^^^^
  File "D:\get_rate_zim\.venv\Lib\site-packages\django\template\loader_tags.py", line 234, in do_block
    nodelist = parser.parse(("endblock",))
               ^^^^^^^^^^^^^^^^^^^^^^^^^^^
  File "D:\get_rate_zim\.venv\Lib\site-packages\django\template\base.py", line 518, in parse
    raise self.error(token, e)
  File "D:\get_rate_zim\.venv\Lib\site-packages\django\template\base.py", line 516, in parse
    compiled_result = compile_func(self, token)
                      ^^^^^^^^^^^^^^^^^^^^^^^^^
  File "D:\get_rate_zim\.venv\Lib\site-packages\django\template\defaulttags.py", line 962, in do_if
    nodelist = parser.parse(("elif", "else", "endif"))
               ^^^^^^^^^^^^^^^^^^^^^^^^^^^^^^^^^^^^^^^
  File "D:\get_rate_zim\.venv\Lib\site-packages\django\template\base.py", line 489, in parse
    raise self.error(token, e)
  File "D:\get_rate_zim\.venv\Lib\site-packages\django\template\base.py", line 487, in parse
    filter_expression = self.compile_filter(token.contents)
                        ^^^^^^^^^^^^^^^^^^^^^^^^^^^^^^^^^^^
  File "D:\get_rate_zim\.venv\Lib\site-packages\django\template\base.py", line 605, in compile_filter
    return FilterExpression(token, self)
           ^^^^^^^^^^^^^^^^^^^^^^^^^^^^^
  File "D:\get_rate_zim\.venv\Lib\site-packages\django\template\base.py", line 701, in __init__
    filter_func = parser.find_filter(filter_name)
                  ^^^^^^^^^^^^^^^^^^^^^^^^^^^^^^^
  File "D:\get_rate_zim\.venv\Lib\site-packages\django\template\base.py", line 611, in find_filter
    raise TemplateSyntaxError("Invalid filter: '%s'" % filter_name)
django.template.exceptions.TemplateSyntaxError: Invalid filter: 'mul'
2025-03-11 16:00:40,391 - rate_predictor.views - ERROR - Error in dashboard task execution: [WinError 10061] No connection could be made because the target machine actively refused it
2025-03-11 16:00:40,453 - django.request - ERROR - Internal Server Error: /rate_predictor/dashboard/
Traceback (most recent call last):
  File "D:\get_rate_zim\.venv\Lib\site-packages\django\core\handlers\exception.py", line 55, in inner
    response = get_response(request)
               ^^^^^^^^^^^^^^^^^^^^^
  File "D:\get_rate_zim\.venv\Lib\site-packages\django\core\handlers\base.py", line 220, in _get_response
    response = response.render()
               ^^^^^^^^^^^^^^^^^
  File "D:\get_rate_zim\.venv\Lib\site-packages\django\template\response.py", line 114, in render
    self.content = self.rendered_content
                   ^^^^^^^^^^^^^^^^^^^^^
  File "D:\get_rate_zim\.venv\Lib\site-packages\django\template\response.py", line 90, in rendered_content
    template = self.resolve_template(self.template_name)
               ^^^^^^^^^^^^^^^^^^^^^^^^^^^^^^^^^^^^^^^^^
  File "D:\get_rate_zim\.venv\Lib\site-packages\django\template\response.py", line 72, in resolve_template
    return select_template(template, using=self.using)
           ^^^^^^^^^^^^^^^^^^^^^^^^^^^^^^^^^^^^^^^^^^^
  File "D:\get_rate_zim\.venv\Lib\site-packages\django\template\loader.py", line 42, in select_template
    return engine.get_template(template_name)
           ^^^^^^^^^^^^^^^^^^^^^^^^^^^^^^^^^^
  File "D:\get_rate_zim\.venv\Lib\site-packages\django\template\backends\django.py", line 79, in get_template
    return Template(self.engine.get_template(template_name), self)
                    ^^^^^^^^^^^^^^^^^^^^^^^^^^^^^^^^^^^^^^^
  File "D:\get_rate_zim\.venv\Lib\site-packages\django\template\engine.py", line 177, in get_template
    template, origin = self.find_template(template_name)
                       ^^^^^^^^^^^^^^^^^^^^^^^^^^^^^^^^^
  File "D:\get_rate_zim\.venv\Lib\site-packages\django\template\engine.py", line 159, in find_template
    template = loader.get_template(name, skip=skip)
               ^^^^^^^^^^^^^^^^^^^^^^^^^^^^^^^^^^^^
  File "D:\get_rate_zim\.venv\Lib\site-packages\django\template\loaders\cached.py", line 57, in get_template
    template = super().get_template(template_name, skip)
               ^^^^^^^^^^^^^^^^^^^^^^^^^^^^^^^^^^^^^^^^^
  File "D:\get_rate_zim\.venv\Lib\site-packages\django\template\loaders\base.py", line 28, in get_template
    return Template(
           ^^^^^^^^^
  File "D:\get_rate_zim\.venv\Lib\site-packages\django\template\base.py", line 154, in __init__
    self.nodelist = self.compile_nodelist()
                    ^^^^^^^^^^^^^^^^^^^^^^^
  File "D:\get_rate_zim\.venv\Lib\site-packages\django\template\base.py", line 196, in compile_nodelist
    nodelist = parser.parse()
               ^^^^^^^^^^^^^^
  File "D:\get_rate_zim\.venv\Lib\site-packages\django\template\base.py", line 519, in parse
    self.extend_nodelist(nodelist, compiled_result, token)
  File "D:\get_rate_zim\.venv\Lib\site-packages\django\template\base.py", line 536, in extend_nodelist
    raise self.error(
django.template.exceptions.TemplateSyntaxError: <ExtendsNode: extends 'base.html'> must be the first tag in the template.
2025-03-11 16:13:37,564 - rate_predictor.views - ERROR - Error in dashboard task execution: [WinError 10061] No connection could be made because the target machine actively refused it
2025-03-11 16:13:37,815 - django.request - WARNING - Not Found: /api/task-progress/
2025-03-13 17:21:20,415 - kombu.connection - WARNING - No hostname was supplied. Reverting to default 'localhost'
2025-03-13 17:21:26,506 - rate_predictor.views - ERROR - Error in dashboard task execution: [WinError 10061] No connection could be made because the target machine actively refused it
2025-03-13 17:21:26,620 - django.request - WARNING - Not Found: /api/task-progress/
2025-03-13 17:32:05,859 - django.utils.autoreload - INFO - D:\get_rate_zim\get_rate_zim\settings.py changed, reloading.
